Workbook

Sheet INTERVENTION ARM
DO8: M
DO9: F
A21: N°Patient | B21: Sex | C21: Age | D21: Height(cm) | E21: Weight (Kg) | F21: PBW(kg) | G21: PAM ini | H21: IMC | I21: VT à 7ml/kg | J21: VT (L) | K21: ETCO2 ini | L21: ΔP ini | M21: RR | N21: RECRUITEMENT PEEP 30 20s | O21: EtCO2 | P21: PAM | Q21: PEEP | R21: ΔP | S21: Ppeak | T21: Pplat | U21: Mechanical Power El Dy (MPdy) [J/min] | V21: Mechanical Power El Stat (MPst) [J/min] | W21: Mechanical Power res (MPres) [J/min] | X21: Temps total protocol (min : s) | Y21: Commentaire | Z21: Ecart-type sur dP(7ml/kg) | AD21: 0.5 | AE21: =AD21 -> 0.5
Q22: 15 | R22: 7 | T22: =R22+Q22 -> 22 | U22: =0.098*J25*M25*0.5*R22 -> 1.5364287 | V22: =0.098*J25*M25*Q22 -> 6.5846945 | W22: ? | AE22: 0
Q23: =Q22-2 -> 13 | R23: X | T23: =R23+Q23 -> #VALUE! | V23: =0.098*J25*M25*Q23 -> 5.7067352 | W23: ? | X23: 0.61111111 | Y23: 0.61111111 | AE23: 0.82
Q24: =Q23-2 -> 11 | R24: 6 | T24: =R24+Q24 -> 17 | U24: =0.098*J25*M25*0.5*R24 -> 1.3169389 | V24: =0.098*J25*M25*Q24 -> 4.828776 | W24: ? | AD24: 0.81649658 | AE24: 0.75
J25: =(7*F28)/1000 -> 0.373282 | K25: 38 | L25: 8 | M25: 12 | Q25: =Q24-2 -> 9 | R25: 6 | T25: =R25+Q25 -> 15 | U25: =0.098*J25*M25*0.5*R25 -> 1.3169389 | V25: =0.098*J25*M25*Q25 -> 3.9508167 | W25: ? | Z25: =_xlfn.STDEV.S(R24:R27) -> 0.5 | AE25: 0.41
Q26: =Q25-2 -> 7 | R26: 6 | T26: =R26+Q26 -> 13 | U26: =0.098*J25*M25*0.5*R26 -> 1.3169389 | V26: =0.098*J25*M25*Q26 -> 3.0728574 | W26: ? | AE26: 0.75
Q27: =Q26-2 -> 5 | R27: 7 | T27: =R27+Q27 -> 12 | U27: =0.098*J25*M25*0.5*R27 -> 1.5364287 | V27: =0.098*J25*M25*Q27 -> 2.1948982 | W27: ? | AA27: Problème (Oui/non) | AD27: 0.75277265 | AE27: 1.33
A28: 1 | B28: F | C28: 61 | D28: 161 | E28: 100 | F28: =IF(B28="M", 50 + 0.91*(D28-152.4), IF(B28="F", 45.5 + 0.91*(D28-152.4), "")) -> 53.326 | G28: 67 | H28: =E28/(D28*10^-2)^2 -> 38.578759 | I28: VT à 9ml/kg | J28: VT | K28: ETCO2 ini | L28: ΔP ini | M28: RR | O28: EtCO2 | P28: PAM | Q28: PEEP | R28: ΔP | S28: Ppeak | T28: Pplat | U28: Mechanical Power El Dy (MPdy)[J/min] | V28: Mechanical Power El Stat (MPst) [J/min] | W28: Mechanical Power res (MPres) [J/min] | Z28: Ecart-type sur dP (9ml/kg) | AA28: OUI | AE28: 0.75
Q29: 15 | R29: X | V29: =0.098*J32*M32*Q29 -> 8.4660358 | W29: ? | AE29: 0.41
Q30: =Q29-2 -> 13 | R30: 7 | U30: =0.098*J32*M32*0.5*R30 -> 1.9754083 | V30: =0.098*J25*M25*Q30 -> 5.7067352 | W30: ? | AD30: 0.40824829 | AE30: 1.47
Q31: =Q30-2 -> 11 | R31: 7 | U31: =0.098*J32*M32*0.5*R31 -> 1.9754083 | V31: =0.098*J25*M25*Q31 -> 4.828776 | W31: ? | AE31: 0.75
J32: =(9*F28)/1000 -> 0.479934 | K32: 38 | L32: 7 | M32: 12 | Q32: =Q31-2 -> 9 | R32: 7 | U32: =0.098*J32*M32*0.5*R32 -> 1.9754083 | V32: =0.098*J25*M25*Q32 -> 3.9508167 | W32: ? | Z32: =_xlfn.STDEV.S(R29:R34) -> 0 | AE32: 1.21
Q33: =Q32-2 -> 7 | R33: 7 | U33: =0.098*J32*M32*0.5*R33 -> 1.9754083 | V33: =0.098*J25*M25*Q33 -> 3.0728574 | W33: ? | AD33: 0.75277265 | AE33: 0.55
Q34: =Q33-2 -> 5 | R34: 7 | U34: =0.098*J32*M32*0.5*R34 -> 1.9754083 | V34: =0.098*J25*M25*Q34 -> 2.1948982 | W34: ? | AE34: 0.41
A35: N°Patient | B35: Sex | C35: Age | D35: Height(cm) | E35: Weight (Kg) | F35: PBW(kg) | G35: PAM ini | H35: IMC | I35: VT à 7ml/kg | J35: VT | K35: ETCO2 ini | L35: ΔP ini | M35: RR | N35: RECRUITEMENT PEEP 30 20s | O35: EtCO2 | P35: PAM | Q35: PEEP | R35: ΔP | S35: Ppeak | T35: Pplat | U35: Mechanical Power El Dy (MPdy) [J/min] | V35: Mechanical Power El Stat (MPst) [J/min] | W35: Mechanical Power res (MPres) [J/min] | X35: Temps total (min : s) | Y35: Commentaire | Z35: Ecart-type sur dP | AE35: 0.52
Q36: 15 | AD36: 1.3291601 | AE36: 0.41
Q37: =Q36-2 -> 13 | X37: 0.5625 | Y37: 0.61111111 | AE37: 1.03
Q38: =Q37-2 -> 11 | R38: =T38-Q38 -> 6 | S38: 19 | T38: 17 | U38: =0.098*J39*M39*0.5*R38 -> 1.4068323 | V38: =0.098*J39*M39*Q38 -> 5.1583852 | W38: =0.098*J39*M39*(S38-T38) -> 0.93788822
J39: =(7*F42)/1000 -> 0.398762 | K39: 30 | L39: 11 | M39: 12 | Q39: =Q38-2 -> 9 | R39: =T39-Q39 -> 6 | S39: 17 | T39: 15 | U39: =0.098*J39*M39*0.5*R39 -> 1.4068323 | V39: =0.098*J39*M39*Q39 -> 4.220497 | W39: =0.098*J39*M39*(S39-T39) -> 0.93788822 | Z39: =_xlfn.STDEV.S(R36:R41) -> 0 | AD39: 0.75277265
Q40: =Q39-2 -> 7 | R40: =T40-Q40 -> 6 | S40: 15 | T40: 13 | U40: =0.098*J39*M39*0.5*R40 -> 1.4068323 | V40: =0.098*J39*M39*Q40 -> 3.2826088 | W40: =0.098*J39*M39*(S40-T40) -> 0.93788822
Q41: =Q40-2 -> 5 | R41: =T41-Q41 -> 6 | S41: 13 | T41: 11 | U41: =0.098*J39*M39*0.5*R41 -> 1.4068323 | V41: =0.098*J39*M39*Q41 -> 2.3447206 | W41: =0.098*J39*M39*(S41-T41) -> 0.93788822 | AA41: Problème (Oui/non)
A42: =A28+1 -> 2 | B42: F | C42: 56 | D42: 165 | E42: 94 | F42: =IF(B42="M", 50 + 0.91*(D42-152.4), IF(B42="F", 45.5 + 0.91*(D42-152.4), "")) -> 56.966 | G42: 72 | H42: =E42/(D42*10^-2)^2 -> 34.527089 | I42: VT à 9ml/kg | J42: VT | K42: ETCO2 ini | L42: ΔP ini | M42: RR | O42: EtCO2 | P42: PAM | Q42: PEEP | R42: ΔP | S42: Ppeak | T42: Pplat | U42: Mechanical Power El Dy (MPdy)[J/min] | V42: Mechanical Power El Stat (MPst) [J/min] | W42: Mechanical Power res (MPres) [J/min] | Z42: Ecart-type sur dP | AA42: OUI | AD42: 0.40824829
Q43: 15 | R43: =T43-Q43 -> 7 | S43: 25 | T43: 22 | U43: =0.098*J46*M46*0.5*R43 -> 1.9343945 | V43: =0.098*J46*M46*Q43 -> 8.290262 | W43: =0.098*J46*M46*(S43-T43) -> 1.6580524
Q44: =Q43-2 -> 13 | R44: =T44-Q44 -> 7 | S44: 22 | T44: 20 | U44: =0.098*J46*M46*0.5*R44 -> 1.9343945 | V44: =0.098*J46*M46*Q44 -> 7.1848937 | W44: =0.098*J46*M46*(S44-T44) -> 1.1053683
Q45: =Q44-2 -> 11 | R45: =T45-Q45 -> 6 | S45: 20 | T45: 17 | U45: =0.098*J46*M46*0.5*R45 -> 1.6580524 | V45: =0.098*J46*M46*Q45 -> 6.0795255 | W45: =0.098*J46*M46*(S45-T45) -> 1.6580524 | AD45: 1.4719601
J46: =(9*F42)/1000 -> 0.512694 | K46: 34 | L46: 3 | M46: 11 | Q46: =Q45-2 -> 9 | R46: =T46-Q46 -> 6 | S46: 18 | T46: 15 | U46: =0.098*J46*M46*0.5*R46 -> 1.6580524 | V46: =0.098*J46*M46*Q46 -> 4.9741572 | W46: =0.098*J46*M46*(S46-T46) -> 1.6580524 | Z46: =_xlfn.STDEV.S(R43:R48) -> 0.51639778
Q47: =Q46-2 -> 7 | R47: =T47-Q47 -> 7 | S47: 16 | T47: 14 | U47: =0.098*J46*M46*0.5*R46 -> 1.6580524 | V47: =0.098*J46*M46*Q47 -> 3.8687889 | W47: =0.098*J46*M46*(S47-T47) -> 1.1053683
Q48: =Q47-2 -> 5 | R48: =T48-Q48 -> 7 | S48: 15 | T48: 12 | U48: =0.098*J46*M46*0.5*R48 -> 1.9343945 | V48: =0.098*J46*M46*Q48 -> 2.7634207 | W48: =0.098*J46*M46*(S48-T48) -> 1.6580524 | AD48: 0.75277265
A49: N°Patient | B49: Sex | C49: Age | D49: Height(cm) | E49: Weight (Kg) | F49: PBW(kg) | G49: PAM ini | H49: IMC | I49: VT à 7ml/kg | J49: VT | K49: ETCO2 ini | L49: ΔP ini | M49: RR | N49: RECRUITEMENT PEEP 30 20s | O49: EtCO2 | P49: PAM | Q49: PEEP | R49: ΔP | S49: Ppeak | T49: Pplat | U49: Mechanical Power El Dy (MPdy) [J/min] | V49: Mechanical Power El Stat (MPst) [J/min] | W49: Mechanical Power res (MPres) [J/min] | X49: Temps total (min : s) | Y49: Commentaire | Z49: Ecart-type sur dP
Q50: 15 | R50: =T50-Q50 -> 8 | S50: 26 | T50: 23 | U50: =0.098*J53*M53*0.5*R50 -> 2.1438104 | V50: =0.098*J53*M53*Q50 -> 8.0392889 | W50: =0.098*J53*M53*(S50-T50) -> 1.6078578
Q51: =Q50-2 -> 13 | R51: =T51-Q51 -> 7 | S51: 22 | T51: 20 | U51: =0.098*J53*M53*0.5*R51 -> 1.8758341 | V51: =0.098*J53*M53*Q51 -> 6.9673837 | W51: =0.098*J53*M53*(S51-T51) -> 1.0719052 | X51: 0.56527778 | Y51: 0.65277778 | AD51: 1.2110601
Q52: =Q51-2 -> 11 | R52: =T52-Q52 -> 7 | S52: 20 | T52: 18 | U52: =0.098*J53*M53*0.5*R52 -> 1.8758341 | V52: =0.098*J53*M53*Q52 -> 5.8954785 | W52: =0.098*J53*M53*(S52-T52) -> 1.0719052
J53: =(7*F56)/1000 -> 0.455742 | K53: 34 | L53: 8 | M53: 12 | Q53: =Q52-2 -> 9 | R53: =T53-Q53 -> 6 | S53: 17 | T53: 15 | U53: =0.098*J53*M53*0.5*R53 -> 1.6078578 | V53: =0.098*J53*M53*Q53 -> 4.8235733 | W53: =0.098*J53*M53*(S53-T53) -> 1.0719052 | Z53: =_xlfn.STDEV.S(R50:R55) -> 0.81649658
Q54: =Q53-2 -> 7 | R54: =T54-Q54 -> 6 | S54: 15 | T54: 13 | U54: =0.098*J53*M53*0.5*R54 -> 1.6078578 | V54: =0.098*J53*M53*Q54 -> 3.7516681 | W54: =0.098*J53*M53*(S54-T54) -> 1.0719052 | AD54: 0.54772256
Q55: =Q54-2 -> 5 | R55: =T55-Q55 -> 6 | S55: 14 | T55: 11 | U55: =0.098*J53*M53*0.5*R55 -> 1.6078578 | V55: =0.098*J53*M53*Q55 -> 2.679763 | W55: =0.098*J53*M53*(S55-T55) -> 1.6078578 | AA55: Problème (Oui/non)
A56: =A42+1 -> 3 | B56: M | C56: 52 | D56: 169 | E56: 59 | F56: =IF(B56="M", 50 + 0.91*(D56-152.4), IF(B56="F", 45.5 + 0.91*(D56-152.4), "")) -> 65.106 | G56: 101 | H56: =E56/(D56*10^-2)^2 -> 20.65754 | I56: VT à 9ml/kg | J56: VT | K56: ETCO2 ini | L56: ΔP ini | M56: RR | O56: EtCO2 | P56: PAM | Q56: PEEP | R56: ΔP | S56: Ppeak | T56: Pplat | U56: Mechanical Power El Dy (MPdy)[J/min] | V56: Mechanical Power El Stat (MPst) [J/min] | W56: Mechanical Power res (MPres) [J/min] | Z56: Ecart-type sur dP | AA56: NON
Q57: 15 | R57: =T57-Q57 -> 10 | S57: 28 | T57: 25 | U57: =0.098*J60*M60*0.5*R57 -> 3.4454095 | V57: =0.098*J60*M60*Q57 -> 10.336229 | W57: =0.098*J60*M60*(S57-T57) -> 2.0672457 | AD57: 0.40824829
Q58: =Q57-2 -> 13 | R58: =T58-Q58 -> 9 | S58: 25 | T58: 22 | U58: =0.098*J60*M60*0.5*R58 -> 3.1008686 | V58: =0.098*J60*M60*Q58 -> 8.9580648 | W58: =0.098*J60*M60*(S58-T58) -> 2.0672457
...

Sheet Results
A1: N°Patient | B1: Sex | C1: Age | D1: Height(cm) | E1: Weight (Kg) | F1: PBW(kg) | G1: IMC | H1: PEEP adaptée (cmH2O) | I1: Pplat (cmH2O) | J1: dp associée (cmH2O) | K1: u(dP) (cmH2O) | L1: Vt adapté(L) | M1: u(Vt) (L) | N1: RR adapté (Cycles/min) | O1: u(RR) (Cycles/min) | P1: Mechanical Pow dyna mini (Vt= 7ml/kg) en J/min | Q1: Mechanical Pow dyna mini (Vt= 9ml/kg) en J/min | R1: Ecart-type de dP (Vt= 7ml/kg) | S1: u(ecart-type) | T1: Écart-type de dP (Vt= 9ml/kg) | U1: Etat décompensé (OUI/NON) | V1: u(Mp dy (7ml/kg)) en J/min | W1: Temps tot protocol (min : s) | X1: Colonne1 | Y1: Colonne2
A2: 1 | B2: =IFERROR(_xlfn.XLOOKUP($A2, 'INTERVENTION ARM'!$A:$A, 'INTERVENTION ARM'!B:B), "") -> F | C2: =IFERROR(_xlfn.XLOOKUP($A2, 'INTERVENTION ARM'!$A:$A, 'INTERVENTION ARM'!C:C), "") -> 61 | D2: =IFERROR(_xlfn.XLOOKUP($A2, 'INTERVENTION ARM'!$A:$A, 'INTERVENTION ARM'!D:D), "") -> 161 | E2: =IFERROR(_xlfn.XLOOKUP($A2, 'INTERVENTION ARM'!$A:$A, 'INTERVENTION ARM'!E:E), "") -> 100 | F2: =IFERROR(_xlfn.XLOOKUP($A2, 'INTERVENTION ARM'!$A:$A, 'INTERVENTION ARM'!F:F), "") -> 53.326 | G2: =IFERROR(_xlfn.XLOOKUP($A2, 'INTERVENTION ARM'!$A:$A, 'INTERVENTION ARM'!H:H), "") -> 38.578759 | H2: {=_xlfn.XLOOKUP(P2, OFFSET('INTERVENTION ARM'!$U$1, MATCH($A2, 'INTERVENTION ARM'!$A:$A, 0) - 7, 0, 6), OFFSET('INTERVENTION ARM'!$Q$1, MATCH($A2, 'INTERVENTION ARM'!$A:$A, 0) - 7, 0, 6), "Non trouvé", 0, -1)} -> 7 | I2: {=_xlfn.XLOOKUP(P2, OFFSET('INTERVENTION ARM'!$U$1, MATCH($A2, 'INTERVENTION ARM'!$A:$A, 0) - 7, 0, 6), OFFSET('INTERVENTION ARM'!$T$1, MATCH($A2, 'INTERVENTION ARM'!$A:$A, 0) - 7, 0, 6), "Non trouvé", 0, -1)} -> 13 | J2: {=_xlfn.XLOOKUP(P2, OFFSET('INTERVENTION ARM'!$U$1, MATCH($A2, 'INTERVENTION ARM'!$A:$A, 0) - 7, 0, 6), OFFSET('INTERVENTION ARM'!$R$1, MATCH($A2, 'INTERVENTION ARM'!$A:$A, 0) - 7, 0, 6), "Non trouvé", 0, -1)} -> 6 | K2: =ROUNDUP(SQRT((Tableau13[[#This Row],[Pplat (cmH2O)]]*0.04)^2+(Tableau13[[#This Row],[PEEP adaptée (cmH2O)]]*0.04)^2),1) -> 0.6 | L2: =MAX(OFFSET('INTERVENTION ARM'!$J$1, MATCH($A2, 'INTERVENTION ARM'!$A:$A, 0) - 7, 0, 6)) -> 0.373282 | M2: =Tableau13[[#This Row],[Vt adapté(L)]]*0.08 -> 0.02986256 | N2: =MAX(OFFSET('INTERVENTION ARM'!$M$1, MATCH($A2, 'INTERVENTION ARM'!$A:$A, 0) - 7, 0, 6)) -> 12 | O2: =Tableau13[[#This Row],[RR adapté (Cycles/min)]]*0.1 -> 1.2 | P2: =IFERROR(MIN(OFFSET('INTERVENTION ARM'!$U$1, MATCH($A2, 'INTERVENTION ARM'!$A:$A, 0) - 7, 0, 6)), "") -> 1.3169389 | Q2: =IFERROR(MIN(OFFSET('INTERVENTION ARM'!$U$1, MATCH($A2, 'INTERVENTION ARM'!$A:$A, 0) + 0, 0, 6)), "") -> 1.9754083 | R2: =IFERROR(MAX(OFFSET('INTERVENTION ARM'!$Z$1, MATCH($A2, 'INTERVENTION ARM'!$A:$A, 0) - 5, 0, 7)), "") -> 0.5 | S2: =Tableau13[[#This Row],[u(dP) (cmH2O)]]/(SQRT(6-1)) -> 0.26832816 | T2: =IFERROR(MAX(OFFSET('INTERVENTION ARM'!$Z$1, MATCH($A2, 'INTERVENTION ARM'!$A:$A, 0) + 2, 0, 7)), "") -> 0 | U2: =IFERROR(_xlfn.XLOOKUP($A2, 'INTERVENTION ARM'!$A:$A, 'INTERVENTION ARM'!AA:AA), "") -> OUI | V2: =SQRT((((0.098*0.5*Tableau13[[#This Row],[RR adapté (Cycles/min)]]*Tableau13[[#This Row],[dp associée (cmH2O)]]*Tableau13[[#This Row],[u(Vt) (L)]])^2)+((0.098*0.5*Tableau13[[#This Row],[Vt adapté(L)]]*Tableau13[[#This Row],[dp associée (cmH2O)]]*Tableau13[[#This Row],[u(RR) (Cycles/min)]])^2)+((0.098*0.5*Tableau13[[#This Row],[Vt adapté(L)]]*Tableau13[[#This Row],[RR adapté (Cycles/min)]]*Tableau13[[#This Row],[u(dP) (cmH2O)]])^2))) -> 0.21397724 | W2: =MAX(OFFSET('INTERVENTION ARM'!$X$1, MATCH($A2, 'INTERVENTION ARM'!$A:$A, 0) - 7, 0, 8)) -> 0.61111111 | AB2: 14
A3: 2 | B3: =IFERROR(_xlfn.XLOOKUP($A3, 'INTERVENTION ARM'!$A:$A, 'INTERVENTION ARM'!B:B), "") -> F | C3: =IFERROR(_xlfn.XLOOKUP($A3, 'INTERVENTION ARM'!$A:$A, 'INTERVENTION ARM'!C:C), "") -> 56 | D3: =IFERROR(_xlfn.XLOOKUP($A3, 'INTERVENTION ARM'!$A:$A, 'INTERVENTION ARM'!D:D), "") -> 165 | E3: =IFERROR(_xlfn.XLOOKUP($A3, 'INTERVENTION ARM'!$A:$A, 'INTERVENTION ARM'!E:E), "") -> 94 | F3: =IFERROR(_xlfn.XLOOKUP($A3, 'INTERVENTION ARM'!$A:$A, 'INTERVENTION ARM'!F:F), "") -> 56.966 | G3: =IFERROR(_xlfn.XLOOKUP($A3, 'INTERVENTION ARM'!$A:$A, 'INTERVENTION ARM'!H:H), "") -> 34.527089 | H3: {=_xlfn.XLOOKUP(P3, OFFSET('INTERVENTION ARM'!$U$1, MATCH($A3, 'INTERVENTION ARM'!$A:$A, 0) - 7, 0, 6), OFFSET('INTERVENTION ARM'!$Q$1, MATCH($A3, 'INTERVENTION ARM'!$A:$A, 0) - 7, 0, 6), "Non trouvé", 0, -1)} -> 5 | I3: {=_xlfn.XLOOKUP(P3, OFFSET('INTERVENTION ARM'!$U$1, MATCH($A3, 'INTERVENTION ARM'!$A:$A, 0) - 7, 0, 6), OFFSET('INTERVENTION ARM'!$T$1, MATCH($A3, 'INTERVENTION ARM'!$A:$A, 0) - 7, 0, 6), "Non trouvé", 0, -1)} -> 11 | J3: {=_xlfn.XLOOKUP(P3, OFFSET('INTERVENTION ARM'!$U$1, MATCH($A3, 'INTERVENTION ARM'!$A:$A, 0) - 7, 0, 6), OFFSET('INTERVENTION ARM'!$R$1, MATCH($A3, 'INTERVENTION ARM'!$A:$A, 0) - 7, 0, 6), "Non trouvé", 0, -1)} -> 6 | K3: =ROUNDUP(SQRT((Tableau13[[#This Row],[Pplat (cmH2O)]]*0.04)^2+(Tableau13[[#This Row],[PEEP adaptée (cmH2O)]]*0.04)^2),1) -> 0.5 | L3: =MAX(OFFSET('INTERVENTION ARM'!$J$1, MATCH($A3, 'INTERVENTION ARM'!$A:$A, 0) - 7, 0, 6)) -> 0.398762 | M3: =Tableau13[[#This Row],[Vt adapté(L)]]*0.08 -> 0.03190096 | N3: =MAX(OFFSET('INTERVENTION ARM'!$M$1, MATCH($A3, 'INTERVENTION ARM'!$A:$A, 0) - 7, 0, 6)) -> 12 | O3: =Tableau13[[#This Row],[RR adapté (Cycles/min)]]*0.1 -> 1.2 | P3: =IFERROR(MIN(OFFSET('INTERVENTION ARM'!$U$1, MATCH($A3, 'INTERVENTION ARM'!$A:$A, 0) - 7, 0, 6)), "") -> 1.4068323 | Q3: =IFERROR(MIN(OFFSET('INTERVENTION ARM'!$U$1, MATCH($A3, 'INTERVENTION ARM'!$A:$A, 0) + 0, 0, 6)), "") -> 1.6580524 | R3: =IFERROR(MAX(OFFSET('INTERVENTION ARM'!$Z$1, MATCH($A3, 'INTERVENTION ARM'!$A:$A, 0) - 5, 0, 7)), "") -> 0 | S3: =Tableau13[[#This Row],[u(dP) (cmH2O)]]/(SQRT(6-1)) -> 0.2236068 | T3: =IFERROR(MAX(OFFSET('INTERVENTION ARM'!$Z$1, MATCH($A3, 'INTERVENTION ARM'!$A:$A, 0) + 2, 0, 7)), "") -> 0.51639778 | U3: =IFERROR(_xlfn.XLOOKUP($A3, 'INTERVENTION ARM'!$A:$A, 'INTERVENTION ARM'!AA:AA), "") -> OUI | V3: =SQRT((((0.098*0.5*Tableau13[[#This Row],[RR adapté (Cycles/min)]]*Tableau13[[#This Row],[dp associée (cmH2O)]]*Tableau13[[#This Row],[u(Vt) (L)]])^2)+((0.098*0.5*Tableau13[[#This Row],[Vt adapté(L)]]*Tableau13[[#This Row],[dp associée (cmH2O)]]*Tableau13[[#This Row],[u(RR) (Cycles/min)]])^2)+((0.098*0.5*Tableau13[[#This Row],[Vt adapté(L)]]*Tableau13[[#This Row],[RR adapté (Cycles/min)]]*Tableau13[[#This Row],[u(dP) (cmH2O)]])^2))) -> 0.21494835 | W3: =MAX(OFFSET('INTERVENTION ARM'!$X$1, MATCH($A3, 'INTERVENTION ARM'!$A:$A, 0) - 7, 0, 8)) -> 0.5625 | AB3: 13
A4: 3 | B4: =IFERROR(_xlfn.XLOOKUP($A4, 'INTERVENTION ARM'!$A:$A, 'INTERVENTION ARM'!B:B), "") -> M | C4: =IFERROR(_xlfn.XLOOKUP($A4, 'INTERVENTION ARM'!$A:$A, 'INTERVENTION ARM'!C:C), "") -> 52 | D4: =IFERROR(_xlfn.XLOOKUP($A4, 'INTERVENTION ARM'!$A:$A, 'INTERVENTION ARM'!D:D), "") -> 169 | E4: =IFERROR(_xlfn.XLOOKUP($A4, 'INTERVENTION ARM'!$A:$A, 'INTERVENTION ARM'!E:E), "") -> 59 | F4: =IFERROR(_xlfn.XLOOKUP($A4, 'INTERVENTION ARM'!$A:$A, 'INTERVENTION ARM'!F:F), "") -> 65.106 | G4: =IFERROR(_xlfn.XLOOKUP($A4, 'INTERVENTION ARM'!$A:$A, 'INTERVENTION ARM'!H:H), "") -> 20.65754 | H4: {=_xlfn.XLOOKUP(P4, OFFSET('INTERVENTION ARM'!$U$1, MATCH($A4, 'INTERVENTION ARM'!$A:$A, 0) - 7, 0, 6), OFFSET('INTERVENTION ARM'!$Q$1, MATCH($A4, 'INTERVENTION ARM'!$A:$A, 0) - 7, 0, 6), "Non trouvé", 0, -1)} -> 5 | I4: {=_xlfn.XLOOKUP(P4, OFFSET('INTERVENTION ARM'!$U$1, MATCH($A4, 'INTERVENTION ARM'!$A:$A, 0) - 7, 0, 6), OFFSET('INTERVENTION ARM'!$T$1, MATCH($A4, 'INTERVENTION ARM'!$A:$A, 0) - 7, 0, 6), "Non trouvé", 0, -1)} -> 11 | J4: {=_xlfn.XLOOKUP(P4, OFFSET('INTERVENTION ARM'!$U$1, MATCH($A4, 'INTERVENTION ARM'!$A:$A, 0) - 7, 0, 6), OFFSET('INTERVENTION ARM'!$R$1, MATCH($A4, 'INTERVENTION ARM'!$A:$A, 0) - 7, 0, 6), "Non trouvé", 0, -1)} -> 6 | K4: =ROUNDUP(SQRT((Tableau13[[#This Row],[Pplat (cmH2O)]]*0.04)^2+(Tableau13[[#This Row],[PEEP adaptée (cmH2O)]]*0.04)^2),1) -> 0.5 | L4: =MAX(OFFSET('INTERVENTION ARM'!$J$1, MATCH($A4, 'INTERVENTION ARM'!$A:$A, 0) - 7, 0, 6)) -> 0.455742 | M4: =Tableau13[[#This Row],[Vt adapté(L)]]*0.08 -> 0.03645936 | N4: =MAX(OFFSET('INTERVENTION ARM'!$M$1, MATCH($A4, 'INTERVENTION ARM'!$A:$A, 0) - 7, 0, 6)) -> 12 | O4: =Tableau13[[#This Row],[RR adapté (Cycles/min)]]*0.1 -> 1.2 | P4: =IFERROR(MIN(OFFSET('INTERVENTION ARM'!$U$1, MATCH($A4, 'INTERVENTION ARM'!$A:$A, 0) - 7, 0, 6)), "") -> 1.6078578 | Q4: =IFERROR(MIN(OFFSET('INTERVENTION ARM'!$U$1, MATCH($A4, 'INTERVENTION ARM'!$A:$A, 0) + 0, 0, 6)), "") -> 2.7563276 | R4: =IFERROR(MAX(OFFSET('INTERVENTION ARM'!$Z$1, MATCH($A4, 'INTERVENTION ARM'!$A:$A, 0) - 5, 0, 7)), "") -> 0.81649658 | S4: =Tableau13[[#This Row],[u(dP) (cmH2O)]]/(SQRT(6-1)) -> 0.2236068 | T4: =IFERROR(MAX(OFFSET('INTERVENTION ARM'!$Z$1, MATCH($A4, 'INTERVENTION ARM'!$A:$A, 0) + 2, 0, 7)), "") -> 0.81649658 | U4: =IFERROR(_xlfn.XLOOKUP($A4, 'INTERVENTION ARM'!$A:$A, 'INTERVENTION ARM'!AA:AA), "") -> NON | V4: =SQRT((((0.098*0.5*Tableau13[[#This Row],[RR adapté (Cycles/min)]]*Tableau13[[#This Row],[dp associée (cmH2O)]]*Tableau13[[#This Row],[u(Vt) (L)]])^2)+((0.098*0.5*Tableau13[[#This Row],[Vt adapté(L)]]*Tableau13[[#This Row],[dp associée (cmH2O)]]*Tableau13[[#This Row],[u(RR) (Cycles/min)]])^2)+((0.098*0.5*Tableau13[[#This Row],[Vt adapté(L)]]*Tableau13[[#This Row],[RR adapté (Cycles/min)]]*Tableau13[[#This Row],[u(dP) (cmH2O)]])^2))) -> 0.2456628 | W4: =MAX(OFFSET('INTERVENTION ARM'!$X$1, MATCH($A4, 'INTERVENTION ARM'!$A:$A, 0) - 7, 0, 8)) -> 0.56527778 | AB4: 13
A5: 4 | B5: =IFERROR(_xlfn.XLOOKUP($A5, 'INTERVENTION ARM'!$A:$A, 'INTERVENTION ARM'!B:B), "") -> F | C5: =IFERROR(_xlfn.XLOOKUP($A5, 'INTERVENTION ARM'!$A:$A, 'INTERVENTION ARM'!C:C), "") -> 63 | D5: =IFERROR(_xlfn.XLOOKUP($A5, 'INTERVENTION ARM'!$A:$A, 'INTERVENTION ARM'!D:D), "") -> 155 | E5: =IFERROR(_xlfn.XLOOKUP($A5, 'INTERVENTION ARM'!$A:$A, 'INTERVENTION ARM'!E:E), "") -> 52 | F5: =IFERROR(_xlfn.XLOOKUP($A5, 'INTERVENTION ARM'!$A:$A, 'INTERVENTION ARM'!F:F), "") -> 47.866 | G5: =IFERROR(_xlfn.XLOOKUP($A5, 'INTERVENTION ARM'!$A:$A, 'INTERVENTION ARM'!H:H), "") -> 21.644121 | H5: {=_xlfn.XLOOKUP(P5, OFFSET('INTERVENTION ARM'!$U$1, MATCH($A5, 'INTERVENTION ARM'!$A:$A, 0) - 7, 0, 6), OFFSET('INTERVENTION ARM'!$Q$1, MATCH($A5, 'INTERVENTION ARM'!$A:$A, 0) - 7, 0, 6), "Non trouvé", 0, -1)} -> 7 | I5: {=_xlfn.XLOOKUP(P5, OFFSET('INTERVENTION ARM'!$U$1, MATCH($A5, 'INTERVENTION ARM'!$A:$A, 0) - 7, 0, 6), OFFSET('INTERVENTION ARM'!$T$1, MATCH($A5, 'INTERVENTION ARM'!$A:$A, 0) - 7, 0, 6), "Non trouvé", 0, -1)} -> 10 | J5: {=_xlfn.XLOOKUP(P5, OFFSET('INTERVENTION ARM'!$U$1, MATCH($A5, 'INTERVENTION ARM'!$A:$A, 0) - 7, 0, 6), OFFSET('INTERVENTION ARM'!$R$1, MATCH($A5, 'INTERVENTION ARM'!$A:$A, 0) - 7, 0, 6), "Non trouvé", 0, -1)} -> 3 | K5: =ROUNDUP(SQRT((Tableau13[[#This Row],[Pplat (cmH2O)]]*0.04)^2+(Tableau13[[#This Row],[PEEP adaptée (cmH2O)]]*0.04)^2),1) -> 0.5 | L5: =MAX(OFFSET('INTERVENTION ARM'!$J$1, MATCH($A5, 'INTERVENTION ARM'!$A:$A, 0) - 7, 0, 6)) -> 0.335062 | M5: =Tableau13[[#This Row],[Vt adapté(L)]]*0.08 -> 0.02680496 | N5: =MAX(OFFSET('INTERVENTION ARM'!$M$1, MATCH($A5, 'INTERVENTION ARM'!$A:$A, 0) - 7, 0, 6)) -> 12 | O5: =Tableau13[[#This Row],[RR adapté (Cycles/min)]]*0.1 -> 1.2 | P5: =IFERROR(MIN(OFFSET('INTERVENTION ARM'!$U$1, MATCH($A5, 'INTERVENTION ARM'!$A:$A, 0) - 7, 0, 6)), "") -> 0.59104937 | Q5: =IFERROR(MIN(OFFSET('INTERVENTION ARM'!$U$1, MATCH($A5, 'INTERVENTION ARM'!$A:$A, 0) + 0, 0, 6)), "") -> 0.92879186 | R5: =IFERROR(MAX(OFFSET('INTERVENTION ARM'!$Z$1, MATCH($A5, 'INTERVENTION ARM'!$A:$A, 0) - 5, 0, 7)), "") -> 0.75277265 | S5: =Tableau13[[#This Row],[u(dP) (cmH2O)]]/(SQRT(6-1)) -> 0.2236068 | T5: =IFERROR(MAX(OFFSET('INTERVENTION ARM'!$Z$1, MATCH($A5, 'INTERVENTION ARM'!$A:$A, 0) + 2, 0, 7)), "") -> 0.54772256 | U5: =IFERROR(_xlfn.XLOOKUP($A5, 'INTERVENTION ARM'!$A:$A, 'INTERVENTION ARM'!AA:AA), "") -> NON | V5: =SQRT((((0.098*0.5*Tableau13[[#This Row],[RR adapté (Cycles/min)]]*Tableau13[[#This Row],[dp associée (cmH2O)]]*Tableau13[[#This Row],[u(Vt) (L)]])^2)+((0.098*0.5*Tableau13[[#This Row],[Vt adapté(L)]]*Tableau13[[#This Row],[dp associée (cmH2O)]]*Tableau13[[#This Row],[u(RR) (Cycles/min)]])^2)+((0.098*0.5*Tableau13[[#This Row],[Vt adapté(L)]]*Tableau13[[#This Row],[RR adapté (Cycles/min)]]*Tableau13[[#This Row],[u(dP) (cmH2O)]])^2))) -> 0.12422977 | W5: =MAX(OFFSET('INTERVENTION ARM'!$X$1, MATCH($A5, 'INTERVENTION ARM'!$A:$A, 0) - 7, 0, 8)) -> 0.64583333 | AB5: 15 | AC5: =_xlfn.STDEV.S(AB2:AB21) -> 3.133436
A6: 5 | B6: =IFERROR(_xlfn.XLOOKUP($A6, 'INTERVENTION ARM'!$A:$A, 'INTERVENTION ARM'!B:B), "") -> M | C6: =IFERROR(_xlfn.XLOOKUP($A6, 'INTERVENTION ARM'!$A:$A, 'INTERVENTION ARM'!C:C), "") -> 34 | D6: =IFERROR(_xlfn.XLOOKUP($A6, 'INTERVENTION ARM'!$A:$A, 'INTERVENTION ARM'!D:D), "") -> 184 | E6: =IFERROR(_xlfn.XLOOKUP($A6, 'INTERVENTION ARM'!$A:$A, 'INTERVENTION ARM'!E:E), "") -> 96 | F6: =IFERROR(_xlfn.XLOOKUP($A6, 'INTERVENTION ARM'!$A:$A, 'INTERVENTION ARM'!F:F), "") -> 78.756 | G6: =IFERROR(_xlfn.XLOOKUP($A6, 'INTERVENTION ARM'!$A:$A, 'INTERVENTION ARM'!H:H), "") -> 28.355388 | H6: {=_xlfn.XLOOKUP(P6, OFFSET('INTERVENTION ARM'!$U$1, MATCH($A6, 'INTERVENTION ARM'!$A:$A, 0) - 7, 0, 6), OFFSET('INTERVENTION ARM'!$Q$1, MATCH($A6, 'INTERVENTION ARM'!$A:$A, 0) - 7, 0, 6), "Non trouvé", 0, -1)} -> 9 | I6: {=_xlfn.XLOOKUP(P6, OFFSET('INTERVENTION ARM'!$U$1, MATCH($A6, 'INTERVENTION ARM'!$A:$A, 0) - 7, 0, 6), OFFSET('INTERVENTION ARM'!$T$1, MATCH($A6, 'INTERVENTION ARM'!$A:$A, 0) - 7, 0, 6), "Non trouvé", 0, -1)} -> 14 | J6: {=_xlfn.XLOOKUP(P6, OFFSET('INTERVENTION ARM'!$U$1, MATCH($A6, 'INTERVENTION ARM'!$A:$A, 0) - 7, 0, 6), OFFSET('INTERVENTION ARM'!$R$1, MATCH($A6, 'INTERVENTION ARM'!$A:$A, 0) - 7, 0, 6), "Non trouvé", 0, -1)} -> 5 | K6: =ROUNDUP(SQRT((Tableau13[[#This Row],[Pplat (cmH2O)]]*0.04)^2+(Tableau13[[#This Row],[PEEP adaptée (cmH2O)]]*0.04)^2),1) -> 0.7 | L6: =MAX(OFFSET('INTERVENTION ARM'!$J$1, MATCH($A6, 'INTERVENTION ARM'!$A:$A, 0) - 7, 0, 6)) -> 0.551292 | M6: =Tableau13[[#This Row],[Vt adapté(L)]]*0.08 -> 0.04410336 | N6: =MAX(OFFSET('INTERVENTION ARM'!$M$1, MATCH($A6, 'INTERVENTION ARM'!$A:$A, 0) - 7, 0, 6)) -> 12 | O6: =Tableau13[[#This Row],[RR adapté (Cycles/min)]]*0.1 -> 1.2 | P6: =IFERROR(MIN(OFFSET('INTERVENTION ARM'!$U$1, MATCH($A6, 'INTERVENTION ARM'!$A:$A, 0) - 7, 0, 6)), "") -> 1.6207985 | Q6: =IFERROR(MIN(OFFSET('INTERVENTION ARM'!$U$1, MATCH($A6, 'INTERVENTION ARM'!$A:$A, 0) + 0, 0, 6)), "") -> 2.9174373 | R6: =IFERROR(MAX(OFFSET('INTERVENTION ARM'!$Z$1, MATCH($A6, 'INTERVENTION ARM'!$A:$A, 0) - 5, 0, 7)), "") -> 0.40824829 | S6: =Tableau13[[#This Row],[u(dP) (cmH2O)]]/(SQRT(6-1)) -> 0.31304952 | T6: =IFERROR(MAX(OFFSET('INTERVENTION ARM'!$Z$1, MATCH($A6, 'INTERVENTION ARM'!$A:$A, 0) + 2, 0, 7)), "") -> 0 | U6: =IFERROR(_xlfn.XLOOKUP($A6, 'INTERVENTION ARM'!$A:$A, 'INTERVENTION ARM'!AA:AA), "") -> OUI | V6: =SQRT((((0.098*0.5*Tableau13[[#This Row],[RR adapté (Cycles/min)]]*Tableau13[[#This Row],[dp associée (cmH2O)]]*Tableau13[[#This Row],[u(Vt) (L)]])^2)+((0.098*0.5*Tableau13[[#This Row],[Vt adapté(L)]]*Tableau13[[#This Row],[dp associée (cmH2O)]]*Tableau13[[#This Row],[u(RR) (Cycles/min)]])^2)+((0.098*0.5*Tableau13[[#This Row],[Vt adapté(L)]]*Tableau13[[#This Row],[RR adapté (Cycles/min)]]*Tableau13[[#This Row],[u(dP) (cmH2O)]])^2))) -> 0.30752489 | W6: =MAX(OFFSET('INTERVENTION ARM'!$X$1, MATCH($A6, 'INTERVENTION ARM'!$A:$A, 0) - 7, 0, 8)) -> 0.625 | AB6: 15
A7: 6 | B7: =IFERROR(_xlfn.XLOOKUP($A7, 'INTERVENTION ARM'!$A:$A, 'INTERVENTION ARM'!B:B), "") -> M | C7: =IFERROR(_xlfn.XLOOKUP($A7, 'INTERVENTION ARM'!$A:$A, 'INTERVENTION ARM'!C:C), "") -> 51 | D7: =IFERROR(_xlfn.XLOOKUP($A7, 'INTERVENTION ARM'!$A:$A, 'INTERVENTION ARM'!D:D), "") -> 162 | E7: =IFERROR(_xlfn.XLOOKUP($A7, 'INTERVENTION ARM'!$A:$A, 'INTERVENTION ARM'!E:E), "") -> 117 | F7: =IFERROR(_xlfn.XLOOKUP($A7, 'INTERVENTION ARM'!$A:$A, 'INTERVENTION ARM'!F:F), "") -> 58.736 | G7: =IFERROR(_xlfn.XLOOKUP($A7, 'INTERVENTION ARM'!$A:$A, 'INTERVENTION ARM'!H:H), "") -> 44.581619 | H7: {=_xlfn.XLOOKUP(P7, OFFSET('INTERVENTION ARM'!$U$1, MATCH($A7, 'INTERVENTION ARM'!$A:$A, 0) - 7, 0, 6), OFFSET('INTERVENTION ARM'!$Q$1, MATCH($A7, 'INTERVENTION ARM'!$A:$A, 0) - 7, 0, 6), "Non trouvé", 0, -1)} -> 15 | I7: {=_xlfn.XLOOKUP(P7, OFFSET('INTERVENTION ARM'!$U$1, MATCH($A7, 'INTERVENTION ARM'!$A:$A, 0) - 7, 0, 6), OFFSET('INTERVENTION ARM'!$T$1, MATCH($A7, 'INTERVENTION ARM'!$A:$A, 0) - 7, 0, 6), "Non trouvé", 0, -1)} -> 24 | J7: {=_xlfn.XLOOKUP(P7, OFFSET('INTERVENTION ARM'!$U$1, MATCH($A7, 'INTERVENTION ARM'!$A:$A, 0) - 7, 0, 6), OFFSET('INTERVENTION ARM'!$R$1, MATCH($A7, 'INTERVENTION ARM'!$A:$A, 0) - 7, 0, 6), "Non trouvé", 0, -1)} -> 9 | K7: =ROUNDUP(SQRT((Tableau13[[#This Row],[Pplat (cmH2O)]]*0.04)^2+(Tableau13[[#This Row],[PEEP adaptée (cmH2O)]]*0.04)^2),1) -> 1.2 | L7: =MAX(OFFSET('INTERVENTION ARM'!$J$1, MATCH($A7, 'INTERVENTION ARM'!$A:$A, 0) - 7, 0, 6)) -> 0.411152 | M7: =Tableau13[[#This Row],[Vt adapté(L)]]*0.08 -> 0.03289216 | N7: =MAX(OFFSET('INTERVENTION ARM'!$M$1, MATCH($A7, 'INTERVENTION ARM'!$A:$A, 0) - 7, 0, 6)) -> 14 | O7: =Tableau13[[#This Row],[RR adapté (Cycles/min)]]*0.1 -> 1.4 | P7: =IFERROR(MIN(OFFSET('INTERVENTION ARM'!$U$1, MATCH($A7, 'INTERVENTION ARM'!$A:$A, 0) - 7, 0, 6)), "") -> 2.5384524 | Q7: =IFERROR(MIN(OFFSET('INTERVENTION ARM'!$U$1, MATCH($A7, 'INTERVENTION ARM'!$A:$A, 0) + 0, 0, 6)), "") -> 3.2637246 | R7: =IFERROR(MAX(OFFSET('INTERVENTION ARM'!$Z$1, MATCH($A7, 'INTERVENTION ARM'!$A:$A, 0) - 5, 0, 7)), "") -> 0.75277265 | S7: =Tableau13[[#This Row],[u(dP) (cmH2O)]]/(SQRT(6-1)) -> 0.53665631 | T7: =IFERROR(MAX(OFFSET('INTERVENTION ARM'!$Z$1, MATCH($A7, 'INTERVENTION ARM'!$A:$A, 0) + 2, 0, 7)), "") -> 2.607681 | U7: =IFERROR(_xlfn.XLOOKUP($A7, 'INTERVENTION ARM'!$A:$A, 'INTERVENTION ARM'!AA:AA), "") -> Oui | V7: =SQRT((((0.098*0.5*Tableau13[[#This Row],[RR adapté (Cycles/min)]]*Tableau13[[#This Row],[dp associée (cmH2O)]]*Tableau13[[#This Row],[u(Vt) (L)]])^2)+((0.098*0.5*Tableau13[[#This Row],[Vt adapté(L)]]*Tableau13[[#This Row],[dp associée (cmH2O)]]*Tableau13[[#This Row],[u(RR) (Cycles/min)]])^2)+((0.098*0.5*Tableau13[[#This Row],[Vt adapté(L)]]*Tableau13[[#This Row],[RR adapté (Cycles/min)]]*Tableau13[[#This Row],[u(dP) (cmH2O)]])^2))) -> 0.46928961 | W7: =MAX(OFFSET('INTERVENTION ARM'!$X$1, MATCH($A7, 'INTERVENTION ARM'!$A:$A, 0) - 7, 0, 8)) -> 0.66666667 | Y7: 17 minutes et 5 secondes | AB7: 16
A8: 7 | B8: =IFERROR(_xlfn.XLOOKUP($A8, 'INTERVENTION ARM'!$A:$A, 'INTERVENTION ARM'!B:B), "") -> M | C8: =IFERROR(_xlfn.XLOOKUP($A8, 'INTERVENTION ARM'!$A:$A, 'INTERVENTION ARM'!C:C), "") -> 67 | D8: =IFERROR(_xlfn.XLOOKUP($A8, 'INTERVENTION ARM'!$A:$A, 'INTERVENTION ARM'!D:D), "") -> 192 | E8: =IFERROR(_xlfn.XLOOKUP($A8, 'INTERVENTION ARM'!$A:$A, 'INTERVENTION ARM'!E:E), "") -> 138 | F8: =IFERROR(_xlfn.XLOOKUP($A8, 'INTERVENTION ARM'!$A:$A, 'INTERVENTION ARM'!F:F), "") -> 86.036 | G8: =IFERROR(_xlfn.XLOOKUP($A8, 'INTERVENTION ARM'!$A:$A, 'INTERVENTION ARM'!H:H), "") -> 37.434896 | H8: {=_xlfn.XLOOKUP(P8, OFFSET('INTERVENTION ARM'!$U$1, MATCH($A8, 'INTERVENTION ARM'!$A:$A, 0) - 7, 0, 6), OFFSET('INTERVENTION ARM'!$Q$1, MATCH($A8, 'INTERVENTION ARM'!$A:$A, 0) - 7, 0, 6), "Non trouvé", 0, -1)} -> 11 | I8: {=_xlfn.XLOOKUP(P8, OFFSET('INTERVENTION ARM'!$U$1, MATCH($A8, 'INTERVENTION ARM'!$A:$A, 0) - 7, 0, 6), OFFSET('INTERVENTION ARM'!$T$1, MATCH($A8, 'INTERVENTION ARM'!$A:$A, 0) - 7, 0, 6), "Non trouvé", 0, -1)} -> 17 | J8: {=_xlfn.XLOOKUP(P8, OFFSET('INTERVENTION ARM'!$U$1, MATCH($A8, 'INTERVENTION ARM'!$A:$A, 0) - 7, 0, 6), OFFSET('INTERVENTION ARM'!$R$1, MATCH($A8, 'INTERVENTION ARM'!$A:$A, 0) - 7, 0, 6), "Non trouvé", 0, -1)} -> 6 | K8: =ROUNDUP(SQRT((Tableau13[[#This Row],[Pplat (cmH2O)]]*0.04)^2+(Tableau13[[#This Row],[PEEP adaptée (cmH2O)]]*0.04)^2),1) -> 0.9 | L8: =MAX(OFFSET('INTERVENTION ARM'!$J$1, MATCH($A8, 'INTERVENTION ARM'!$A:$A, 0) - 7, 0, 6)) -> 0.602252 | M8: =Tableau13[[#This Row],[Vt adapté(L)]]*0.08 -> 0.04818016 | N8: =MAX(OFFSET('INTERVENTION ARM'!$M$1, MATCH($A8, 'INTERVENTION ARM'!$A:$A, 0) - 7, 0, 6)) -> 12 | O8: =Tableau13[[#This Row],[RR adapté (Cycles/min)]]*0.1 -> 1.2 | P8: =IFERROR(MIN(OFFSET('INTERVENTION ARM'!$U$1, MATCH($A8, 'INTERVENTION ARM'!$A:$A, 0) - 7, 0, 6)), "") -> 2.1247451 | Q8: =IFERROR(MIN(OFFSET('INTERVENTION ARM'!$U$1, MATCH($A8, 'INTERVENTION ARM'!$A:$A, 0) + 0, 0, 6)), "") -> 3.6424201 | R8: =IFERROR(MAX(OFFSET('INTERVENTION ARM'!$Z$1, MATCH($A8, 'INTERVENTION ARM'!$A:$A, 0) - 5, 0, 7)), "") -> 1.3291601 | S8: =Tableau13[[#This Row],[u(dP) (cmH2O)]]/(SQRT(6-1)) -> 0.40249224 | T8: =IFERROR(MAX(OFFSET('INTERVENTION ARM'!$Z$1, MATCH($A8, 'INTERVENTION ARM'!$A:$A, 0) + 2, 0, 7)), "") -> 0.51639778 | U8: =IFERROR(_xlfn.XLOOKUP($A8, 'INTERVENTION ARM'!$A:$A, 'INTERVENTION ARM'!AA:AA), "") -> Oui | V8: =SQRT((((0.098*0.5*Tableau13[[#This Row],[RR adapté (Cycles/min)]]*Tableau13[[#This Row],[dp associée (cmH2O)]]*Tableau13[[#This Row],[u(Vt) (L)]])^2)+((0.098*0.5*Tableau13[[#This Row],[Vt adapté(L)]]*Tableau13[[#This Row],[dp associée (cmH2O)]]*Tableau13[[#This Row],[u(RR) (Cycles/min)]])^2)+((0.098*0.5*Tableau13[[#This Row],[Vt adapté(L)]]*Tableau13[[#This Row],[RR adapté (Cycles/min)]]*Tableau13[[#This Row],[u(dP) (cmH2O)]])^2))) -> 0.41906523 | W8: =MAX(OFFSET('INTERVENTION ARM'!$X$1, MATCH($A8, 'INTERVENTION ARM'!$A:$A, 0) - 7, 0, 8)) -> 0.66666667 | AB8: 16
A9: 8 | B9: =IFERROR(_xlfn.XLOOKUP($A9, 'INTERVENTION ARM'!$A:$A, 'INTERVENTION ARM'!B:B), "") -> F | C9: =IFERROR(_xlfn.XLOOKUP($A9, 'INTERVENTION ARM'!$A:$A, 'INTERVENTION ARM'!C:C), "") -> 38 | D9: =IFERROR(_xlfn.XLOOKUP($A9, 'INTERVENTION ARM'!$A:$A, 'INTERVENTION ARM'!D:D), "") -> 163 | E9: =IFERROR(_xlfn.XLOOKUP($A9, 'INTERVENTION ARM'!$A:$A, 'INTERVENTION ARM'!E:E), "") -> 80 | F9: =IFERROR(_xlfn.XLOOKUP($A9, 'INTERVENTION ARM'!$A:$A, 'INTERVENTION ARM'!F:F), "") -> 55.146 | G9: =IFERROR(_xlfn.XLOOKUP($A9, 'INTERVENTION ARM'!$A:$A, 'INTERVENTION ARM'!H:H), "") -> 30.110279 | H9: {=_xlfn.XLOOKUP(P9, OFFSET('INTERVENTION ARM'!$U$1, MATCH($A9, 'INTERVENTION ARM'!$A:$A, 0) - 7, 0, 6), OFFSET('INTERVENTION ARM'!$Q$1, MATCH($A9, 'INTERVENTION ARM'!$A:$A, 0) - 7, 0, 6), "Non trouvé", 0, -1)} -> 7 | I9: {=_xlfn.XLOOKUP(P9, OFFSET('INTERVENTION ARM'!$U$1, MATCH($A9, 'INTERVENTION ARM'!$A:$A, 0) - 7, 0, 6), OFFSET('INTERVENTION ARM'!$T$1, MATCH($A9, 'INTERVENTION ARM'!$A:$A, 0) - 7, 0, 6), "Non trouvé", 0, -1)} -> 14 | J9: {=_xlfn.XLOOKUP(P9, OFFSET('INTERVENTION ARM'!$U$1, MATCH($A9, 'INTERVENTION ARM'!$A:$A, 0) - 7, 0, 6), OFFSET('INTERVENTION ARM'!$R$1, MATCH($A9, 'INTERVENTION ARM'!$A:$A, 0) - 7, 0, 6), "Non trouvé", 0, -1)} -> 7 | K9: =ROUNDUP(SQRT((Tableau13[[#This Row],[Pplat (cmH2O)]]*0.04)^2+(Tableau13[[#This Row],[PEEP adaptée (cmH2O)]]*0.04)^2),1) -> 0.7 | L9: =MAX(OFFSET('INTERVENTION ARM'!$J$1, MATCH($A9, 'INTERVENTION ARM'!$A:$A, 0) - 7, 0, 6)) -> 0.386022 | M9: =Tableau13[[#This Row],[Vt adapté(L)]]*0.08 -> 0.03088176 | N9: =MAX(OFFSET('INTERVENTION ARM'!$M$1, MATCH($A9, 'INTERVENTION ARM'!$A:$A, 0) - 7, 0, 6)) -> 14 | O9: =Tableau13[[#This Row],[RR adapté (Cycles/min)]]*0.1 -> 1.4 | P9: =IFERROR(MIN(OFFSET('INTERVENTION ARM'!$U$1, MATCH($A9, 'INTERVENTION ARM'!$A:$A, 0) - 7, 0, 6)), "") -> 1.8536776 | Q9: =IFERROR(MIN(OFFSET('INTERVENTION ARM'!$U$1, MATCH($A9, 'INTERVENTION ARM'!$A:$A, 0) + 0, 0, 6)), "") -> 3.404714 | R9: =IFERROR(MAX(OFFSET('INTERVENTION ARM'!$Z$1, MATCH($A9, 'INTERVENTION ARM'!$A:$A, 0) - 5, 0, 7)), "") -> 0.75277265 | S9: =Tableau13[[#This Row],[u(dP) (cmH2O)]]/(SQRT(6-1)) -> 0.31304952 | T9: =IFERROR(MAX(OFFSET('INTERVENTION ARM'!$Z$1, MATCH($A9, 'INTERVENTION ARM'!$A:$A, 0) + 2, 0, 7)), "") -> 0.54772256 | U9: =IFERROR(_xlfn.XLOOKUP($A9, 'INTERVENTION ARM'!$A:$A, 'INTERVENTION ARM'!AA:AA), "") -> NON | V9: =SQRT((((0.098*0.5*Tableau13[[#This Row],[RR adapté (Cycles/min)]]*Tableau13[[#This Row],[dp associée (cmH2O)]]*Tableau13[[#This Row],[u(Vt) (L)]])^2)+((0.098*0.5*Tableau13[[#This Row],[Vt adapté(L)]]*Tableau13[[#This Row],[dp associée (cmH2O)]]*Tableau13[[#This Row],[u(RR) (Cycles/min)]])^2)+((0.098*0.5*Tableau13[[#This Row],[Vt adapté(L)]]*Tableau13[[#This Row],[RR adapté (Cycles/min)]]*Tableau13[[#This Row],[u(dP) (cmH2O)]])^2))) -> 0.30118697 | W9: =MAX(OFFSET('INTERVENTION ARM'!$X$1, MATCH($A9, 'INTERVENTION ARM'!$A:$A, 0) - 7, 0, 8)) -> 0.95833333 | AB9: 23
A10: 9 | B10: =IFERROR(_xlfn.XLOOKUP($A10, 'INTERVENTION ARM'!$A:$A, 'INTERVENTION ARM'!B:B), "") -> F | C10: =IFERROR(_xlfn.XLOOKUP($A10, 'INTERVENTION ARM'!$A:$A, 'INTERVENTION ARM'!C:C), "") -> 48 | D10: =IFERROR(_xlfn.XLOOKUP($A10, 'INTERVENTION ARM'!$A:$A, 'INTERVENTION ARM'!D:D), "") -> 155 | E10: =IFERROR(_xlfn.XLOOKUP($A10, 'INTERVENTION ARM'!$A:$A, 'INTERVENTION ARM'!E:E), "") -> 80 | F10: =IFERROR(_xlfn.XLOOKUP($A10, 'INTERVENTION ARM'!$A:$A, 'INTERVENTION ARM'!F:F), "") -> 47.866 | G10: =IFERROR(_xlfn.XLOOKUP($A10, 'INTERVENTION ARM'!$A:$A, 'INTERVENTION ARM'!H:H), "") -> 33.298647 | H10: {=_xlfn.XLOOKUP(P10, OFFSET('INTERVENTION ARM'!$U$1, MATCH($A10, 'INTERVENTION ARM'!$A:$A, 0) - 7, 0, 6), OFFSET('INTERVENTION ARM'!$Q$1, MATCH($A10, 'INTERVENTION ARM'!$A:$A, 0) - 7, 0, 6), "Non trouvé", 0, -1)} -> 7 | I10: {=_xlfn.XLOOKUP(P10, OFFSET('INTERVENTION ARM'!$U$1, MATCH($A10, 'INTERVENTION ARM'!$A:$A, 0) - 7, 0, 6), OFFSET('INTERVENTION ARM'!$T$1, MATCH($A10, 'INTERVENTION ARM'!$A:$A, 0) - 7, 0, 6), "Non trouvé", 0, -1)} -> 12 | J10: {=_xlfn.XLOOKUP(P10, OFFSET('INTERVENTION ARM'!$U$1, MATCH($A10, 'INTERVENTION ARM'!$A:$A, 0) - 7, 0, 6), OFFSET('INTERVENTION ARM'!$R$1, MATCH($A10, 'INTERVENTION ARM'!$A:$A, 0) - 7, 0, 6), "Non trouvé", 0, -1)} -> 5 | K10: =ROUNDUP(SQRT((Tableau13[[#This Row],[Pplat (cmH2O)]]*0.04)^2+(Tableau13[[#This Row],[PEEP adaptée (cmH2O)]]*0.04)^2),1) -> 0.6 | L10: =MAX(OFFSET('INTERVENTION ARM'!$J$1, MATCH($A10, 'INTERVENTION ARM'!$A:$A, 0) - 7, 0, 6)) -> 0.335062 | M10: =Tableau13[[#This Row],[Vt adapté(L)]]*0.08 -> 0.02680496 | N10: =MAX(OFFSET('INTERVENTION ARM'!$M$1, MATCH($A10, 'INTERVENTION ARM'!$A:$A, 0) - 7, 0, 6)) -> 14 | O10: =Tableau13[[#This Row],[RR adapté (Cycles/min)]]*0.1 -> 1.4 | P10: =IFERROR(MIN(OFFSET('INTERVENTION ARM'!$U$1, MATCH($A10, 'INTERVENTION ARM'!$A:$A, 0) - 7, 0, 6)), "") -> 1.1492627 | Q10: =IFERROR(MIN(OFFSET('INTERVENTION ARM'!$U$1, MATCH($A10, 'INTERVENTION ARM'!$A:$A, 0) + 0, 0, 6)), "") -> 1.8998015 | R10: =IFERROR(MAX(OFFSET('INTERVENTION ARM'!$Z$1, MATCH($A10, 'INTERVENTION ARM'!$A:$A, 0) - 5, 0, 7)), "") -> 0.40824829 | S10: =Tableau13[[#This Row],[u(dP) (cmH2O)]]/(SQRT(6-1)) -> 0.26832816 | T10: =IFERROR(MAX(OFFSET('INTERVENTION ARM'!$Z$1, MATCH($A10, 'INTERVENTION ARM'!$A:$A, 0) + 2, 0, 7)), "") -> 0.40824829 | U10: =IFERROR(_xlfn.XLOOKUP($A10, 'INTERVENTION ARM'!$A:$A, 'INTERVENTION ARM'!AA:AA), "") -> Oui | V10: =SQRT((((0.098*0.5*Tableau13[[#This Row],[RR adapté (Cycles/min)]]*Tableau13[[#This Row],[dp associée (cmH2O)]]*Tableau13[[#This Row],[u(Vt) (L)]])^2)+((0.098*0.5*Tableau13[[#This Row],[Vt adapté(L)]]*Tableau13[[#This Row],[dp associée (cmH2O)]]*Tableau13[[#This Row],[u(RR) (Cycles/min)]])^2)+((0.098*0.5*Tableau13[[#This Row],[Vt adapté(L)]]*Tableau13[[#This Row],[RR adapté (Cycles/min)]]*Tableau13[[#This Row],[u(dP) (cmH2O)]])^2))) -> 0.20169478 | W10: =MAX(OFFSET('INTERVENTION ARM'!$X$1, MATCH($A10, 'INTERVENTION ARM'!$A:$A, 0) - 7, 0, 8)) -> 0.65277778 | AB10: 15
A11: 10 | B11: =IFERROR(_xlfn.XLOOKUP($A11, 'INTERVENTION ARM'!$A:$A, 'INTERVENTION ARM'!B:B), "") -> M | C11: =IFERROR(_xlfn.XLOOKUP($A11, 'INTERVENTION ARM'!$A:$A, 'INTERVENTION ARM'!C:C), "") -> 35 | D11: =IFERROR(_xlfn.XLOOKUP($A11, 'INTERVENTION ARM'!$A:$A, 'INTERVENTION ARM'!D:D), "") -> 167 | E11: =IFERROR(_xlfn.XLOOKUP($A11, 'INTERVENTION ARM'!$A:$A, 'INTERVENTION ARM'!E:E), "") -> 130 | F11: =IFERROR(_xlfn.XLOOKUP($A11, 'INTERVENTION ARM'!$A:$A, 'INTERVENTION ARM'!F:F), "") -> 63.286 | G11: =IFERROR(_xlfn.XLOOKUP($A11, 'INTERVENTION ARM'!$A:$A, 'INTERVENTION ARM'!H:H), "") -> 46.61336 | H11: {=_xlfn.XLOOKUP(P11, OFFSET('INTERVENTION ARM'!$U$1, MATCH($A11, 'INTERVENTION ARM'!$A:$A, 0) - 7, 0, 6), OFFSET('INTERVENTION ARM'!$Q$1, MATCH($A11, 'INTERVENTION ARM'!$A:$A, 0) - 7, 0, 6), "Non trouvé", 0, -1)} -> 13 | I11: {=_xlfn.XLOOKUP(P11, OFFSET('INTERVENTION ARM'!$U$1, MATCH($A11, 'INTERVENTION ARM'!$A:$A, 0) - 7, 0, 6), OFFSET('INTERVENTION ARM'!$T$1, MATCH($A11, 'INTERVENTION ARM'!$A:$A, 0) - 7, 0, 6), "Non trouvé", 0, -1)} -> 19 | J11: {=_xlfn.XLOOKUP(P11, OFFSET('INTERVENTION ARM'!$U$1, MATCH($A11, 'INTERVENTION ARM'!$A:$A, 0) - 7, 0, 6), OFFSET('INTERVENTION ARM'!$R$1, MATCH($A11, 'INTERVENTION ARM'!$A:$A, 0) - 7, 0, 6), "Non trouvé", 0, -1)} -> 6 | K11: =ROUNDUP(SQRT((Tableau13[[#This Row],[Pplat (cmH2O)]]*0.04)^2+(Tableau13[[#This Row],[PEEP adaptée (cmH2O)]]*0.04)^2),1) -> 1 | L11: =MAX(OFFSET('INTERVENTION ARM'!$J$1, MATCH($A11, 'INTERVENTION ARM'!$A:$A, 0) - 7, 0, 6)) -> 0.443002 | M11: =Tableau13[[#This Row],[Vt adapté(L)]]*0.08 -> 0.03544016 | N11: =MAX(OFFSET('INTERVENTION ARM'!$M$1, MATCH($A11, 'INTERVENTION ARM'!$A:$A, 0) - 7, 0, 6)) -> 20 | O11: =Tableau13[[#This Row],[RR adapté (Cycles/min)]]*0.1 -> 2 | P11: =IFERROR(MIN(OFFSET('INTERVENTION ARM'!$U$1, MATCH($A11, 'INTERVENTION ARM'!$A:$A, 0) - 7, 0, 6)), "") -> 2.6048518 | Q11: =IFERROR(MIN(OFFSET('INTERVENTION ARM'!$U$1, MATCH($A11, 'INTERVENTION ARM'!$A:$A, 0) + 0, 0, 6)), "") -> 4.4654602 | R11: =IFERROR(MAX(OFFSET('INTERVENTION ARM'!$Z$1, MATCH($A11, 'INTERVENTION ARM'!$A:$A, 0) - 5, 0, 7)), "") -> 1.4719601 | S11: =Tableau13[[#This Row],[u(dP) (cmH2O)]]/(SQRT(6-1)) -> 0.4472136 | T11: =IFERROR(MAX(OFFSET('INTERVENTION ARM'!$Z$1, MATCH($A11, 'INTERVENTION ARM'!$A:$A, 0) + 2, 0, 7)), "") -> 1.3291601 | U11: =IFERROR(_xlfn.XLOOKUP($A11, 'INTERVENTION ARM'!$A:$A, 'INTERVENTION ARM'!AA:AA), "") -> Oui | V11: =SQRT((((0.098*0.5*Tableau13[[#This Row],[RR adapté (Cycles/min)]]*Tableau13[[#This Row],[dp associée (cmH2O)]]*Tableau13[[#This Row],[u(Vt) (L)]])^2)+((0.098*0.5*Tableau13[[#This Row],[Vt adapté(L)]]*Tableau13[[#This Row],[dp associée (cmH2O)]]*Tableau13[[#This Row],[u(RR) (Cycles/min)]])^2)+((0.098*0.5*Tableau13[[#This Row],[Vt adapté(L)]]*Tableau13[[#This Row],[RR adapté (Cycles/min)]]*Tableau13[[#This Row],[u(dP) (cmH2O)]])^2))) -> 0.54750104 | W11: =MAX(OFFSET('INTERVENTION ARM'!$X$1, MATCH($A11, 'INTERVENTION ARM'!$A:$A, 0) - 7, 0, 8)) -> 0.625 | AB11: 15
A12: 11 | B12: =IFERROR(_xlfn.XLOOKUP($A12, 'INTERVENTION ARM'!$A:$A, 'INTERVENTION ARM'!B:B), "") -> F | C12: =IFERROR(_xlfn.XLOOKUP($A12, 'INTERVENTION ARM'!$A:$A, 'INTERVENTION ARM'!C:C), "") -> 26 | D12: =IFERROR(_xlfn.XLOOKUP($A12, 'INTERVENTION ARM'!$A:$A, 'INTERVENTION ARM'!D:D), "") -> 178 | E12: =IFERROR(_xlfn.XLOOKUP($A12, 'INTERVENTION ARM'!$A:$A, 'INTERVENTION ARM'!E:E), "") -> 140 | F12: =IFERROR(_xlfn.XLOOKUP($A12, 'INTERVENTION ARM'!$A:$A, 'INTERVENTION ARM'!F:F), "") -> 68.796 | G12: =IFERROR(_xlfn.XLOOKUP($A12, 'INTERVENTION ARM'!$A:$A, 'INTERVENTION ARM'!H:H), "") -> 44.18634 | H12: {=_xlfn.XLOOKUP(P12, OFFSET('INTERVENTION ARM'!$U$1, MATCH($A12, 'INTERVENTION ARM'!$A:$A, 0) - 7, 0, 6), OFFSET('INTERVENTION ARM'!$Q$1, MATCH($A12, 'INTERVENTION ARM'!$A:$A, 0) - 7, 0, 6), "Non trouvé", 0, -1)} -> 13 | I12: {=_xlfn.XLOOKUP(P12, OFFSET('INTERVENTION ARM'!$U$1, MATCH($A12, 'INTERVENTION ARM'!$A:$A, 0) - 7, 0, 6), OFFSET('INTERVENTION ARM'!$T$1, MATCH($A12, 'INTERVENTION ARM'!$A:$A, 0) - 7, 0, 6), "Non trouvé", 0, -1)} -> 18 | J12: {=_xlfn.XLOOKUP(P12, OFFSET('INTERVENTION ARM'!$U$1, MATCH($A12, 'INTERVENTION ARM'!$A:$A, 0) - 7, 0, 6), OFFSET('INTERVENTION ARM'!$R$1, MATCH($A12, 'INTERVENTION ARM'!$A:$A, 0) - 7, 0, 6), "Non trouvé", 0, -1)} -> 5 | K12: =ROUNDUP(SQRT((Tableau13[[#This Row],[Pplat (cmH2O)]]*0.04)^2+(Tableau13[[#This Row],[PEEP adaptée (cmH2O)]]*0.04)^2),1) -> 0.9 | L12: =MAX(OFFSET('INTERVENTION ARM'!$J$1, MATCH($A12, 'INTERVENTION ARM'!$A:$A, 0) - 7, 0, 6)) -> 0.481572 | M12: =Tableau13[[#This Row],[Vt adapté(L)]]*0.08 -> 0.03852576 | N12: =MAX(OFFSET('INTERVENTION ARM'!$M$1, MATCH($A12, 'INTERVENTION ARM'!$A:$A, 0) - 7, 0, 6)) -> 13 | O12: =Tableau13[[#This Row],[RR adapté (Cycles/min)]]*0.1 -> 1.3 | P12: =IFERROR(MIN(OFFSET('INTERVENTION ARM'!$U$1, MATCH($A12, 'INTERVENTION ARM'!$A:$A, 0) - 7, 0, 6)), "") -> 1.5338068 | Q12: =IFERROR(MIN(OFFSET('INTERVENTION ARM'!$U$1, MATCH($A12, 'INTERVENTION ARM'!$A:$A, 0) + 0, 0, 6)), "") -> 2.4271229 | R12: =IFERROR(MAX(OFFSET('INTERVENTION ARM'!$Z$1, MATCH($A12, 'INTERVENTION ARM'!$A:$A, 0) - 5, 0, 7)), "") -> 0.75277265 | S12: =Tableau13[[#This Row],[u(dP) (cmH2O)]]/(SQRT(6-1)) -> 0.40249224 | T12: =IFERROR(MAX(OFFSET('INTERVENTION ARM'!$Z$1, MATCH($A12, 'INTERVENTION ARM'!$A:$A, 0) + 2, 0, 7)), "") -> 0 | U12: =IFERROR(_xlfn.XLOOKUP($A12, 'INTERVENTION ARM'!$A:$A, 'INTERVENTION ARM'!AA:AA), "") -> Oui | V12: =SQRT((((0.098*0.5*Tableau13[[#This Row],[RR adapté (Cycles/min)]]*Tableau13[[#This Row],[dp associée (cmH2O)]]*Tableau13[[#This Row],[u(Vt) (L)]])^2)+((0.098*0.5*Tableau13[[#This Row],[Vt adapté(L)]]*Tableau13[[#This Row],[dp associée (cmH2O)]]*Tableau13[[#This Row],[u(RR) (Cycles/min)]])^2)+((0.098*0.5*Tableau13[[#This Row],[Vt adapté(L)]]*Tableau13[[#This Row],[RR adapté (Cycles/min)]]*Tableau13[[#This Row],[u(dP) (cmH2O)]])^2))) -> 0.338829 | W12: =MAX(OFFSET('INTERVENTION ARM'!$X$1, MATCH($A12, 'INTERVENTION ARM'!$A:$A, 0) - 7, 0, 8)) -> 0.875 | AB12: 21
A13: 12 | B13: =IFERROR(_xlfn.XLOOKUP($A13, 'INTERVENTION ARM'!$A:$A, 'INTERVENTION ARM'!B:B), "") -> M | C13: =IFERROR(_xlfn.XLOOKUP($A13, 'INTERVENTION ARM'!$A:$A, 'INTERVENTION ARM'!C:C), "") -> 88 | D13: =IFERROR(_xlfn.XLOOKUP($A13, 'INTERVENTION ARM'!$A:$A, 'INTERVENTION ARM'!D:D), "") -> 170 | E13: =IFERROR(_xlfn.XLOOKUP($A13, 'INTERVENTION ARM'!$A:$A, 'INTERVENTION ARM'!E:E), "") -> 61 | F13: =IFERROR(_xlfn.XLOOKUP($A13, 'INTERVENTION ARM'!$A:$A, 'INTERVENTION ARM'!F:F), "") -> 66.016 | G13: =IFERROR(_xlfn.XLOOKUP($A13, 'INTERVENTION ARM'!$A:$A, 'INTERVENTION ARM'!H:H), "") -> 21.107266 | H13: {=_xlfn.XLOOKUP(P13, OFFSET('INTERVENTION ARM'!$U$1, MATCH($A13, 'INTERVENTION ARM'!$A:$A, 0) - 7, 0, 6), OFFSET('INTERVENTION ARM'!$Q$1, MATCH($A13, 'INTERVENTION ARM'!$A:$A, 0) - 7, 0, 6), "Non trouvé", 0, -1)} -> 5 | I13: {=_xlfn.XLOOKUP(P13, OFFSET('INTERVENTION ARM'!$U$1, MATCH($A13, 'INTERVENTION ARM'!$A:$A, 0) - 7, 0, 6), OFFSET('INTERVENTION ARM'!$T$1, MATCH($A13, 'INTERVENTION ARM'!$A:$A, 0) - 7, 0, 6), "Non trouvé", 0, -1)} -> 14 | J13: {=_xlfn.XLOOKUP(P13, OFFSET('INTERVENTION ARM'!$U$1, MATCH($A13, 'INTERVENTION ARM'!$A:$A, 0) - 7, 0, 6), OFFSET('INTERVENTION ARM'!$R$1, MATCH($A13, 'INTERVENTION ARM'!$A:$A, 0) - 7, 0, 6), "Non trouvé", 0, -1)} -> 9 | K13: =ROUNDUP(SQRT((Tableau13[[#This Row],[Pplat (cmH2O)]]*0.04)^2+(Tableau13[[#This Row],[PEEP adaptée (cmH2O)]]*0.04)^2),1) -> 0.6 | L13: =MAX(OFFSET('INTERVENTION ARM'!$J$1, MATCH($A13, 'INTERVENTION ARM'!$A:$A, 0) - 7, 0, 6)) -> 0.462112 | M13: =Tableau13[[#This Row],[Vt adapté(L)]]*0.08 -> 0.03696896 | N13: =MAX(OFFSET('INTERVENTION ARM'!$M$1, MATCH($A13, 'INTERVENTION ARM'!$A:$A, 0) - 7, 0, 6)) -> 11 | O13: =Tableau13[[#This Row],[RR adapté (Cycles/min)]]*0.1 -> 1.1 | P13: =IFERROR(MIN(OFFSET('INTERVENTION ARM'!$U$1, MATCH($A13, 'INTERVENTION ARM'!$A:$A, 0) - 7, 0, 6)), "") -> 2.2417053 | Q13: =IFERROR(MIN(OFFSET('INTERVENTION ARM'!$U$1, MATCH($A13, 'INTERVENTION ARM'!$A:$A, 0) + 0, 0, 6)), "") -> 3.9302626 | R13: =IFERROR(MAX(OFFSET('INTERVENTION ARM'!$Z$1, MATCH($A13, 'INTERVENTION ARM'!$A:$A, 0) - 5, 0, 7)), "") -> 1.2110601 | S13: =Tableau13[[#This Row],[u(dP) (cmH2O)]]/(SQRT(6-1)) -> 0.26832816 | T13: =IFERROR(MAX(OFFSET('INTERVENTION ARM'!$Z$1, MATCH($A13, 'INTERVENTION ARM'!$A:$A, 0) + 2, 0, 7)), "") -> 1.2649111 | U13: =IFERROR(_xlfn.XLOOKUP($A13, 'INTERVENTION ARM'!$A:$A, 'INTERVENTION ARM'!AA:AA), "") -> Oui | V13: =SQRT((((0.098*0.5*Tableau13[[#This Row],[RR adapté (Cycles/min)]]*Tableau13[[#This Row],[dp associée (cmH2O)]]*Tableau13[[#This Row],[u(Vt) (L)]])^2)+((0.098*0.5*Tableau13[[#This Row],[Vt adapté(L)]]*Tableau13[[#This Row],[dp associée (cmH2O)]]*Tableau13[[#This Row],[u(RR) (Cycles/min)]])^2)+((0.098*0.5*Tableau13[[#This Row],[Vt adapté(L)]]*Tableau13[[#This Row],[RR adapté (Cycles/min)]]*Tableau13[[#This Row],[u(dP) (cmH2O)]])^2))) -> 0.32364856 | W13: =MAX(OFFSET('INTERVENTION ARM'!$X$1, MATCH($A13, 'INTERVENTION ARM'!$A:$A, 0) - 7, 0, 8)) -> 0.83333333 | AB13: 20
A14: 13 | B14: =IFERROR(_xlfn.XLOOKUP($A14, 'INTERVENTION ARM'!$A:$A, 'INTERVENTION ARM'!B:B), "") -> M | C14: =IFERROR(_xlfn.XLOOKUP($A14, 'INTERVENTION ARM'!$A:$A, 'INTERVENTION ARM'!C:C), "") -> 61 | D14: =IFERROR(_xlfn.XLOOKUP($A14, 'INTERVENTION ARM'!$A:$A, 'INTERVENTION ARM'!D:D), "") -> 185 | E14: =IFERROR(_xlfn.XLOOKUP($A14, 'INTERVENTION ARM'!$A:$A, 'INTERVENTION ARM'!E:E), "") -> 85 | F14: =IFERROR(_xlfn.XLOOKUP($A14, 'INTERVENTION ARM'!$A:$A, 'INTERVENTION ARM'!F:F), "") -> 79.666 | G14: =IFERROR(_xlfn.XLOOKUP($A14, 'INTERVENTION ARM'!$A:$A, 'INTERVENTION ARM'!H:H), "") -> 24.835646 | H14: {=_xlfn.XLOOKUP(P14, OFFSET('INTERVENTION ARM'!$U$1, MATCH($A14, 'INTERVENTION ARM'!$A:$A, 0) - 7, 0, 6), OFFSET('INTERVENTION ARM'!$Q$1, MATCH($A14, 'INTERVENTION ARM'!$A:$A, 0) - 7, 0, 6), "Non trouvé", 0, -1)} -> 9 | I14: {=_xlfn.XLOOKUP(P14, OFFSET('INTERVENTION ARM'!$U$1, MATCH($A14, 'INTERVENTION ARM'!$A:$A, 0) - 7, 0, 6), OFFSET('INTERVENTION ARM'!$T$1, MATCH($A14, 'INTERVENTION ARM'!$A:$A, 0) - 7, 0, 6), "Non trouvé", 0, -1)} -> 16 | J14: {=_xlfn.XLOOKUP(P14, OFFSET('INTERVENTION ARM'!$U$1, MATCH($A14, 'INTERVENTION ARM'!$A:$A, 0) - 7, 0, 6), OFFSET('INTERVENTION ARM'!$R$1, MATCH($A14, 'INTERVENTION ARM'!$A:$A, 0) - 7, 0, 6), "Non trouvé", 0, -1)} -> 7 | K14: =ROUNDUP(SQRT((Tableau13[[#This Row],[Pplat (cmH2O)]]*0.04)^2+(Tableau13[[#This Row],[PEEP adaptée (cmH2O)]]*0.04)^2),1) -> 0.8 | L14: =MAX(OFFSET('INTERVENTION ARM'!$J$1, MATCH($A14, 'INTERVENTION ARM'!$A:$A, 0) - 7, 0, 6)) -> 0.557662 | M14: =Tableau13[[#This Row],[Vt adapté(L)]]*0.08 -> 0.04461296 | N14: =MAX(OFFSET('INTERVENTION ARM'!$M$1, MATCH($A14, 'INTERVENTION ARM'!$A:$A, 0) - 7, 0, 6)) -> 11 | O14: =Tableau13[[#This Row],[RR adapté (Cycles/min)]]*0.1 -> 1.1 | P14: =IFERROR(MIN(OFFSET('INTERVENTION ARM'!$U$1, MATCH($A14, 'INTERVENTION ARM'!$A:$A, 0) - 7, 0, 6)), "") -> 2.1040587 | Q14: =IFERROR(MIN(OFFSET('INTERVENTION ARM'!$U$1, MATCH($A14, 'INTERVENTION ARM'!$A:$A, 0) + 0, 0, 6)), "") -> 3.4781379 | R14: =IFERROR(MAX(OFFSET('INTERVENTION ARM'!$Z$1, MATCH($A14, 'INTERVENTION ARM'!$A:$A, 0) - 5, 0, 7)), "") -> 0.54772256 | S14: =Tableau13[[#This Row],[u(dP) (cmH2O)]]/(SQRT(6-1)) -> 0.35777088 | T14: =IFERROR(MAX(OFFSET('INTERVENTION ARM'!$Z$1, MATCH($A14, 'INTERVENTION ARM'!$A:$A, 0) + 2, 0, 7)), "") -> 0.54772256 | U14: =IFERROR(_xlfn.XLOOKUP($A14, 'INTERVENTION ARM'!$A:$A, 'INTERVENTION ARM'!AA:AA), "") -> Oui | V14: =SQRT((((0.098*0.5*Tableau13[[#This Row],[RR adapté (Cycles/min)]]*Tableau13[[#This Row],[dp associée (cmH2O)]]*Tableau13[[#This Row],[u(Vt) (L)]])^2)+((0.098*0.5*Tableau13[[#This Row],[Vt adapté(L)]]*Tableau13[[#This Row],[dp associée (cmH2O)]]*Tableau13[[#This Row],[u(RR) (Cycles/min)]])^2)+((0.098*0.5*Tableau13[[#This Row],[Vt adapté(L)]]*Tableau13[[#This Row],[RR adapté (Cycles/min)]]*Tableau13[[#This Row],[u(dP) (cmH2O)]])^2))) -> 0.36114637 | W14: =MAX(OFFSET('INTERVENTION ARM'!$X$1, MATCH($A14, 'INTERVENTION ARM'!$A:$A, 0) - 7, 0, 8)) -> 0.60972222 | AB14: 14
A15: 14 | B15: =IFERROR(_xlfn.XLOOKUP($A15, 'INTERVENTION ARM'!$A:$A, 'INTERVENTION ARM'!B:B), "") -> F | C15: =IFERROR(_xlfn.XLOOKUP($A15, 'INTERVENTION ARM'!$A:$A, 'INTERVENTION ARM'!C:C), "") -> 58 | D15: =IFERROR(_xlfn.XLOOKUP($A15, 'INTERVENTION ARM'!$A:$A, 'INTERVENTION ARM'!D:D), "") -> 163 | E15: =IFERROR(_xlfn.XLOOKUP($A15, 'INTERVENTION ARM'!$A:$A, 'INTERVENTION ARM'!E:E), "") -> 63 | F15: =IFERROR(_xlfn.XLOOKUP($A15, 'INTERVENTION ARM'!$A:$A, 'INTERVENTION ARM'!F:F), "") -> 55.146 | G15: =IFERROR(_xlfn.XLOOKUP($A15, 'INTERVENTION ARM'!$A:$A, 'INTERVENTION ARM'!H:H), "") -> 23.711845 | H15: {=_xlfn.XLOOKUP(P15, OFFSET('INTERVENTION ARM'!$U$1, MATCH($A15, 'INTERVENTION ARM'!$A:$A, 0) - 7, 0, 6), OFFSET('INTERVENTION ARM'!$Q$1, MATCH($A15, 'INTERVENTION ARM'!$A:$A, 0) - 7, 0, 6), "Non trouvé", 0, -1)} -> 7 | I15: {=_xlfn.XLOOKUP(P15, OFFSET('INTERVENTION ARM'!$U$1, MATCH($A15, 'INTERVENTION ARM'!$A:$A, 0) - 7, 0, 6), OFFSET('INTERVENTION ARM'!$T$1, MATCH($A15, 'INTERVENTION ARM'!$A:$A, 0) - 7, 0, 6), "Non trouvé", 0, -1)} -> 13 | J15: {=_xlfn.XLOOKUP(P15, OFFSET('INTERVENTION ARM'!$U$1, MATCH($A15, 'INTERVENTION ARM'!$A:$A, 0) - 7, 0, 6), OFFSET('INTERVENTION ARM'!$R$1, MATCH($A15, 'INTERVENTION ARM'!$A:$A, 0) - 7, 0, 6), "Non trouvé", 0, -1)} -> 6 | K15: =ROUNDUP(SQRT((Tableau13[[#This Row],[Pplat (cmH2O)]]*0.04)^2+(Tableau13[[#This Row],[PEEP adaptée (cmH2O)]]*0.04)^2),1) -> 0.6 | L15: =MAX(OFFSET('INTERVENTION ARM'!$J$1, MATCH($A15, 'INTERVENTION ARM'!$A:$A, 0) - 7, 0, 6)) -> 0.386022 | M15: =Tableau13[[#This Row],[Vt adapté(L)]]*0.08 -> 0.03088176 | N15: =MAX(OFFSET('INTERVENTION ARM'!$M$1, MATCH($A15, 'INTERVENTION ARM'!$A:$A, 0) - 7, 0, 6)) -> 13 | O15: =Tableau13[[#This Row],[RR adapté (Cycles/min)]]*0.1 -> 1.3 | P15: =IFERROR(MIN(OFFSET('INTERVENTION ARM'!$U$1, MATCH($A15, 'INTERVENTION ARM'!$A:$A, 0) - 7, 0, 6)), "") -> 1.4753761 | Q15: =IFERROR(MIN(OFFSET('INTERVENTION ARM'!$U$1, MATCH($A15, 'INTERVENTION ARM'!$A:$A, 0) + 0, 0, 6)), "") -> 1.8969121 | R15: =IFERROR(MAX(OFFSET('INTERVENTION ARM'!$Z$1, MATCH($A15, 'INTERVENTION ARM'!$A:$A, 0) - 5, 0, 7)), "") -> 0.40824829 | S15: =Tableau13[[#This Row],[u(dP) (cmH2O)]]/(SQRT(6-1)) -> 0.26832816 | T15: =IFERROR(MAX(OFFSET('INTERVENTION ARM'!$Z$1, MATCH($A15, 'INTERVENTION ARM'!$A:$A, 0) + 2, 0, 7)), "") -> 0.51639778 | U15: =IFERROR(_xlfn.XLOOKUP($A15, 'INTERVENTION ARM'!$A:$A, 'INTERVENTION ARM'!AA:AA), "") -> Oui | V15: =SQRT((((0.098*0.5*Tableau13[[#This Row],[RR adapté (Cycles/min)]]*Tableau13[[#This Row],[dp associée (cmH2O)]]*Tableau13[[#This Row],[u(Vt) (L)]])^2)+((0.098*0.5*Tableau13[[#This Row],[Vt adapté(L)]]*Tableau13[[#This Row],[dp associée (cmH2O)]]*Tableau13[[#This Row],[u(RR) (Cycles/min)]])^2)+((0.098*0.5*Tableau13[[#This Row],[Vt adapté(L)]]*Tableau13[[#This Row],[RR adapté (Cycles/min)]]*Tableau13[[#This Row],[u(dP) (cmH2O)]])^2))) -> 0.23972024 | W15: =MAX(OFFSET('INTERVENTION ARM'!$X$1, MATCH($A15, 'INTERVENTION ARM'!$A:$A, 0) - 7, 0, 8)) -> 0.73263889 | AB15: 17
A16: 15 | B16: =IFERROR(_xlfn.XLOOKUP($A16, 'INTERVENTION ARM'!$A:$A, 'INTERVENTION ARM'!B:B), "") -> M | C16: =IFERROR(_xlfn.XLOOKUP($A16, 'INTERVENTION ARM'!$A:$A, 'INTERVENTION ARM'!C:C), "") -> 76 | D16: =IFERROR(_xlfn.XLOOKUP($A16, 'INTERVENTION ARM'!$A:$A, 'INTERVENTION ARM'!D:D), "") -> 175 | E16: =IFERROR(_xlfn.XLOOKUP($A16, 'INTERVENTION ARM'!$A:$A, 'INTERVENTION ARM'!E:E), "") -> 95 | F16: =IFERROR(_xlfn.XLOOKUP($A16, 'INTERVENTION ARM'!$A:$A, 'INTERVENTION ARM'!F:F), "") -> 70.566 | G16: =IFERROR(_xlfn.XLOOKUP($A16, 'INTERVENTION ARM'!$A:$A, 'INTERVENTION ARM'!H:H), "") -> 31.020408 | H16: {=_xlfn.XLOOKUP(P16, OFFSET('INTERVENTION ARM'!$U$1, MATCH($A16, 'INTERVENTION ARM'!$A:$A, 0) - 7, 0, 6), OFFSET('INTERVENTION ARM'!$Q$1, MATCH($A16, 'INTERVENTION ARM'!$A:$A, 0) - 7, 0, 6), "Non trouvé", 0, -1)} -> 7 | I16: {=_xlfn.XLOOKUP(P16, OFFSET('INTERVENTION ARM'!$U$1, MATCH($A16, 'INTERVENTION ARM'!$A:$A, 0) - 7, 0, 6), OFFSET('INTERVENTION ARM'!$T$1, MATCH($A16, 'INTERVENTION ARM'!$A:$A, 0) - 7, 0, 6), "Non trouvé", 0, -1)} -> 14 | J16: {=_xlfn.XLOOKUP(P16, OFFSET('INTERVENTION ARM'!$U$1, MATCH($A16, 'INTERVENTION ARM'!$A:$A, 0) - 7, 0, 6), OFFSET('INTERVENTION ARM'!$R$1, MATCH($A16, 'INTERVENTION ARM'!$A:$A, 0) - 7, 0, 6), "Non trouvé", 0, -1)} -> 7 | K16: =ROUNDUP(SQRT((Tableau13[[#This Row],[Pplat (cmH2O)]]*0.04)^2+(Tableau13[[#This Row],[PEEP adaptée (cmH2O)]]*0.04)^2),1) -> 0.7 | L16: =MAX(OFFSET('INTERVENTION ARM'!$J$1, MATCH($A16, 'INTERVENTION ARM'!$A:$A, 0) - 7, 0, 6)) -> 0.493962 | M16: =Tableau13[[#This Row],[Vt adapté(L)]]*0.08 -> 0.03951696 | N16: =MAX(OFFSET('INTERVENTION ARM'!$M$1, MATCH($A16, 'INTERVENTION ARM'!$A:$A, 0) - 7, 0, 6)) -> 11 | O16: =Tableau13[[#This Row],[RR adapté (Cycles/min)]]*0.1 -> 1.1 | P16: =IFERROR(MIN(OFFSET('INTERVENTION ARM'!$U$1, MATCH($A16, 'INTERVENTION ARM'!$A:$A, 0) - 7, 0, 6)), "") -> 1.8637186 | Q16: =IFERROR(MIN(OFFSET('INTERVENTION ARM'!$U$1, MATCH($A16, 'INTERVENTION ARM'!$A:$A, 0) + 0, 0, 6)), "") -> 3.6409939 | R16: =IFERROR(MAX(OFFSET('INTERVENTION ARM'!$Z$1, MATCH($A16, 'INTERVENTION ARM'!$A:$A, 0) - 5, 0, 7)), "") -> 0.51639778 | S16: =Tableau13[[#This Row],[u(dP) (cmH2O)]]/(SQRT(6-1)) -> 0.31304952 | T16: =IFERROR(MAX(OFFSET('INTERVENTION ARM'!$Z$1, MATCH($A16, 'INTERVENTION ARM'!$A:$A, 0) + 2, 0, 7)), "") -> 0.63245553 | U16: =IFERROR(_xlfn.XLOOKUP($A16, 'INTERVENTION ARM'!$A:$A, 'INTERVENTION ARM'!AA:AA), "") -> Oui | V16: =SQRT((((0.098*0.5*Tableau13[[#This Row],[RR adapté (Cycles/min)]]*Tableau13[[#This Row],[dp associée (cmH2O)]]*Tableau13[[#This Row],[u(Vt) (L)]])^2)+((0.098*0.5*Tableau13[[#This Row],[Vt adapté(L)]]*Tableau13[[#This Row],[dp associée (cmH2O)]]*Tableau13[[#This Row],[u(RR) (Cycles/min)]])^2)+((0.098*0.5*Tableau13[[#This Row],[Vt adapté(L)]]*Tableau13[[#This Row],[RR adapté (Cycles/min)]]*Tableau13[[#This Row],[u(dP) (cmH2O)]])^2))) -> 0.30281843 | W16: =MAX(OFFSET('INTERVENTION ARM'!$X$1, MATCH($A16, 'INTERVENTION ARM'!$A:$A, 0) - 7, 0, 8)) -> 0.79166667 | AB16: 19
A17: 16 | B17: =IFERROR(_xlfn.XLOOKUP($A17, 'INTERVENTION ARM'!$A:$A, 'INTERVENTION ARM'!B:B), "") -> M | C17: =IFERROR(_xlfn.XLOOKUP($A17, 'INTERVENTION ARM'!$A:$A, 'INTERVENTION ARM'!C:C), "") -> 67 | D17: =IFERROR(_xlfn.XLOOKUP($A17, 'INTERVENTION ARM'!$A:$A, 'INTERVENTION ARM'!D:D), "") -> 180 | E17: =IFERROR(_xlfn.XLOOKUP($A17, 'INTERVENTION ARM'!$A:$A, 'INTERVENTION ARM'!E:E), "") -> 120 | F17: =IFERROR(_xlfn.XLOOKUP($A17, 'INTERVENTION ARM'!$A:$A, 'INTERVENTION ARM'!F:F), "") -> 75.116 | G17: =IFERROR(_xlfn.XLOOKUP($A17, 'INTERVENTION ARM'!$A:$A, 'INTERVENTION ARM'!H:H), "") -> 37.037037 | H17: {=_xlfn.XLOOKUP(P17, OFFSET('INTERVENTION ARM'!$U$1, MATCH($A17, 'INTERVENTION ARM'!$A:$A, 0) - 7, 0, 6), OFFSET('INTERVENTION ARM'!$Q$1, MATCH($A17, 'INTERVENTION ARM'!$A:$A, 0) - 7, 0, 6), "Non trouvé", 0, -1)} -> 7 | I17: {=_xlfn.XLOOKUP(P17, OFFSET('INTERVENTION ARM'!$U$1, MATCH($A17, 'INTERVENTION ARM'!$A:$A, 0) - 7, 0, 6), OFFSET('INTERVENTION ARM'!$T$1, MATCH($A17, 'INTERVENTION ARM'!$A:$A, 0) - 7, 0, 6), "Non trouvé", 0, -1)} -> 16 | J17: {=_xlfn.XLOOKUP(P17, OFFSET('INTERVENTION ARM'!$U$1, MATCH($A17, 'INTERVENTION ARM'!$A:$A, 0) - 7, 0, 6), OFFSET('INTERVENTION ARM'!$R$1, MATCH($A17, 'INTERVENTION ARM'!$A:$A, 0) - 7, 0, 6), "Non trouvé", 0, -1)} -> 9 | K17: =ROUNDUP(SQRT((Tableau13[[#This Row],[Pplat (cmH2O)]]*0.04)^2+(Tableau13[[#This Row],[PEEP adaptée (cmH2O)]]*0.04)^2),1) -> 0.7 | L17: =MAX(OFFSET('INTERVENTION ARM'!$J$1, MATCH($A17, 'INTERVENTION ARM'!$A:$A, 0) - 7, 0, 6)) -> 0.525812 | M17: =Tableau13[[#This Row],[Vt adapté(L)]]*0.08 -> 0.04206496 | N17: =MAX(OFFSET('INTERVENTION ARM'!$M$1, MATCH($A17, 'INTERVENTION ARM'!$A:$A, 0) - 7, 0, 6)) -> 10 | O17: =Tableau13[[#This Row],[RR adapté (Cycles/min)]]*0.1 -> 1 | P17: =IFERROR(MIN(OFFSET('INTERVENTION ARM'!$U$1, MATCH($A17, 'INTERVENTION ARM'!$A:$A, 0) - 7, 0, 6)), "") -> 2.3188309 | Q17: =IFERROR(MIN(OFFSET('INTERVENTION ARM'!$U$1, MATCH($A17, 'INTERVENTION ARM'!$A:$A, 0) + 0, 0, 6)), "") -> 3.180111 | R17: =IFERROR(MAX(OFFSET('INTERVENTION ARM'!$Z$1, MATCH($A17, 'INTERVENTION ARM'!$A:$A, 0) - 5, 0, 7)), "") -> 0.40824829 | S17: =Tableau13[[#This Row],[u(dP) (cmH2O)]]/(SQRT(6-1)) -> 0.31304952 | T17: =IFERROR(MAX(OFFSET('INTERVENTION ARM'!$Z$1, MATCH($A17, 'INTERVENTION ARM'!$A:$A, 0) + 2, 0, 7)), "") -> 9.4109865 | U17: =IFERROR(_xlfn.XLOOKUP($A17, 'INTERVENTION ARM'!$A:$A, 'INTERVENTION ARM'!AA:AA), "") -> Oui | V17: =SQRT((((0.098*0.5*Tableau13[[#This Row],[RR adapté (Cycles/min)]]*Tableau13[[#This Row],[dp associée (cmH2O)]]*Tableau13[[#This Row],[u(Vt) (L)]])^2)+((0.098*0.5*Tableau13[[#This Row],[Vt adapté(L)]]*Tableau13[[#This Row],[dp associée (cmH2O)]]*Tableau13[[#This Row],[u(RR) (Cycles/min)]])^2)+((0.098*0.5*Tableau13[[#This Row],[Vt adapté(L)]]*Tableau13[[#This Row],[RR adapté (Cycles/min)]]*Tableau13[[#This Row],[u(dP) (cmH2O)]])^2))) -> 0.34743317 | W17: =MAX(OFFSET('INTERVENTION ARM'!$X$1, MATCH($A17, 'INTERVENTION ARM'!$A:$A, 0) - 7, 0, 8)) -> 0.75 | AB17: 18
